<?xml version="1.0" encoding="utf-8"?>
<!-- This URDF was automatically created by SolidWorks to URDF Exporter! Originally created by Stephen Brawner (brawner@gmail.com) 
     Commit Version: 1.6.0-4-g7f85cfe  Build Version: 1.6.7995.38578
     For more information, please see http://wiki.ros.org/sw_urdf_exporter -->
<robot
  name="omni_ballbot">

  <mujoco>
    <compiler meshdir="../meshes/" balanceinertia="true" discardvisual="false"/>
</mujoco>

<!--主体-->
  <link
    name="base_link">
    <inertial>
      <origin
        xyz="0.00087466 -6.742E-07 -0.024251"
        rpy="0 0 0" />
      <mass
        value="0.71641" />
      <inertia
        ixx="0.002093"
        ixy="-9.5735E-10"
        ixz="3.1765E-09"
        iyy="0.0020657"
        iyz="-2.4415E-10"
        izz="0.0040571" />
    </inertial>
    <visual>
      <origin
        xyz="0 0 0"
        rpy="0 0 0" />
      <geometry>
        <mesh
          filename="package://omni_ballbot/meshes/base_link.STL" />
      </geometry>
      <material
        name="">
        <color
          rgba="1 1 1 1" />
      </material>
    </visual>
    <collision>
      <origin
        xyz="0 0 0"
        rpy="0 0 0" />
      <geometry>
        <cylinder radius="0.1" length="0.04" />
      </geometry>
    </collision>
  </link>
<!--wheel1-->
  <joint
    name="wheel1_joint"
    type="continuous">
    <origin
      xyz="0.18364 0 -0.081395"
      rpy="0 0.69813 0" />
    <parent
      link="base_link" />
    <child
      link="wheel1_base" />
    <axis
      xyz="1 0 0" />
  </joint>
<!--wheel1_轮毂-->
  <link
    name="wheel1_base">
    <inertial>
      <origin
        xyz="-1.0842E-18 -6.5486E-17 -3.7297E-17"
        rpy="0 0 0" />
      <mass
        value="0.033709" />
      <inertia
        ixx="1.0185E-05"
        ixy="-1.2283E-23"
        ixz="-7.157E-23"
        iyy="5.1179E-06"
        iyz="1.5882E-21"
        izz="5.1179E-06" />
    </inertial>
    <visual>
      <origin
        xyz="0 0 0"
        rpy="0 0 0" />
      <geometry>
        <mesh
          filename="package://omni_ballbot/meshes/wheel_base.STL" />
      </geometry>
      <material
        name="">
        <color
          rgba="1 1 1 1" />
      </material>
    </visual>
    <collision>
      <origin
        xyz="0 0 0"
        rpy="0 0 0" />
      <geometry>
        <mesh
          filename="package://omni_ballbot/meshes/wheel_base.STL" />
      </geometry>
    </collision>
  </link>
  <link
    name="wheel1_link_A1">
    <inertial>
      <origin
        xyz="1.979E-14 9.4195E-16 -4.0874E-16"
        rpy="0 0 0" />
      <mass
        value="0.016346" />
      <inertia
        ixx="2.0983E-06"
        ixy="-1.9323E-20"
        ixz="-2.7123E-23"
        iyy="1.2396E-06"
        iyz="-2.9302E-21"
        izz="2.0983E-06" />
    </inertial>
    <visual>
      <origin
        xyz="0 0 0"
        rpy="0 0 0" />
      <geometry>
        <mesh
          filename="package://omni_ballbot/meshes/wheel_link_A.STL" />
      </geometry>
      <material
        name="">
        <color
          rgba="1 1 1 1" />
      </material>
    </visual>
    <collision>
      <origin
        xyz="0 0 0"
        rpy="0 0 0" />
      <geometry>
        <mesh
          filename="package://omni_ballbot/meshes/wheel_link_A.STL" />
      </geometry>
    </collision>
  </link>
  <joint
    name="wheel1_joint_A1"
    type="continuous">
    <origin
      xyz="0 0 0.052"
      rpy="0 -1.5708 0" />
    <parent
      link="wheel1_base" />
    <child
      link="wheel1_link_A1" />
    <axis
      xyz="0 1 0" />
  </joint>
  <link
    name="wheel1_link_A2">
    <inertial>
      <origin
        xyz="1.97897254139434E-14 8.22258927613007E-16 -4.09611580765024E-16"
        rpy="0 0 0" />
      <mass
        value="0.0163461071966825" />
      <inertia
        ixx="2.09834716259754E-06"
        ixy="-1.51248320644096E-19"
        ixz="-4.90262679480716E-23"
        iyy="1.23958351383999E-06"
        iyz="-2.9163765855995E-21"
        izz="2.09834716259754E-06" />
    </inertial>
    <visual>
      <origin
        xyz="0 0 0"
        rpy="0 0 0" />
      <geometry>
        <mesh
          filename="package://omni_ballbot/meshes/wheel_link_A.STL" />
      </geometry>
      <material
        name="">
        <color
          rgba="1 1 1 1" />
      </material>
    </visual>
    <collision>
      <origin
        xyz="0 0 0"
        rpy="0 0 0" />
      <geometry>
        <mesh
          filename="package://omni_ballbot/meshes/wheel_link_A.STL" />
      </geometry>
    </collision>
  </link>
  <joint
    name="wheel1_joint_A2"
    type="continuous">
    <origin
      xyz="0 -0.045033 0.026"
      rpy="1.5708 -0.5236 -1.5708" />
    <parent
      link="wheel1_base" />
    <child
      link="wheel1_link_A2" />
    <axis
      xyz="0 1 0" />
  </joint>
  <link
    name="wheel1_link_A3">
    <inertial>
      <origin
        xyz="1.9776E-14 7.494E-16 -4.0961E-16"
        rpy="0 0 0" />
      <mass
        value="0.016346" />
      <inertia
        ixx="2.0983E-06"
        ixy="-2.2896E-20"
        ixz="-4.9433E-23"
        iyy="1.2396E-06"
        iyz="-2.8665E-21"
        izz="2.0983E-06" />
    </inertial>
    <visual>
      <origin
        xyz="0 0 0"
        rpy="0 0 0" />
      <geometry>
        <mesh
          filename="package://omni_ballbot/meshes/wheel_link_A.STL" />
      </geometry>
      <material
        name="">
        <color
          rgba="1 1 1 1" />
      </material>
    </visual>
    <collision>
      <origin
        xyz="0 0 0"
        rpy="0 0 0" />
      <geometry>
        <mesh
          filename="package://omni_ballbot/meshes/wheel_link_A.STL" />
      </geometry>
    </collision>
  </link>
  <joint
    name="wheel1_joint_A3"
    type="continuous">
    <origin
      xyz="0 -0.045033 -0.026"
      rpy="1.5708 0.5236 -1.5708" />
    <parent
      link="wheel1_base" />
    <child
      link="wheel1_link_A3" />
    <axis
      xyz="0 1 0" />
  </joint>
  <link
    name="wheel1_link_A4">
    <inertial>
      <origin
        xyz="-7.63278329429795E-17 7.45931094670027E-17 -1.64798730217797E-17"
        rpy="0 0 0" />
      <mass
        value="0.0163461071966825" />
      <inertia
        ixx="2.09834716259755E-06"
        ixy="-7.30565917006834E-21"
        ixz="-1.9688018747927E-23"
        iyy="1.23958351383999E-06"
        iyz="-2.74827099200293E-21"
        izz="2.09834716259755E-06" />
    </inertial>
    <visual>
      <origin
        xyz="0 0 0"
        rpy="0 0 0" />
      <geometry>
        <mesh
          filename="package://omni_ballbot/meshes/wheel_link_A.STL" />
      </geometry>
      <material
        name="">
        <color
          rgba="1 1 1 1" />
      </material>
    </visual>
    <collision>
      <origin
        xyz="0 0 0"
        rpy="0 0 0" />
      <geometry>
        <mesh
          filename="package://omni_ballbot/meshes/wheel_link_A.STL" />
      </geometry>
    </collision>
  </link>
  <joint
    name="wheel1_joint_A4"
    type="continuous">
    <origin
      xyz="0 0 -0.052"
      rpy="3.1416 1.5708 0" />
    <parent
      link="wheel1_base" />
    <child
      link="wheel1_link_A4" />
    <axis
      xyz="0 1 0" />
  </joint>
  <link
    name="wheel1_link_A5">
    <inertial>
      <origin
        xyz="1.9776E-14 1.2039E-15 -4.0918E-16"
        rpy="0 0 0" />
      <mass
        value="0.016346" />
      <inertia
        ixx="2.0983E-06"
        ixy="-1.4929E-20"
        ixz="-5.3997E-23"
        iyy="1.2396E-06"
        iyz="-2.869E-21"
        izz="2.0983E-06" />
    </inertial>
    <visual>
      <origin
        xyz="0 0 0"
        rpy="0 0 0" />
      <geometry>
        <mesh
          filename="package://omni_ballbot/meshes/wheel_link_A.STL" />
      </geometry>
      <material
        name="">
        <color
          rgba="1 1 1 1" />
      </material>
    </visual>
    <collision>
      <origin
        xyz="0 0 0"
        rpy="0 0 0" />
      <geometry>
        <mesh
          filename="package://omni_ballbot/meshes/wheel_link_A.STL" />
      </geometry>
    </collision>
  </link>
  <joint
    name="wheel1_joint_A5"
    type="continuous">
    <origin
      xyz="0 0.045033 -0.026"
      rpy="-1.5708 0.5236 1.5708" />
    <parent
      link="wheel1_base" />
    <child
      link="wheel1_link_A5" />
    <axis
      xyz="0 1 0" />
  </joint>
  <link
    name="wheel1_link_A6">
    <inertial>
      <origin
        xyz="1.9811E-14 1.0738E-15 -4.0896E-16"
        rpy="0 0 0" />
      <mass
        value="0.016346" />
      <inertia
        ixx="2.0983E-06"
        ixy="-1.7364E-20"
        ixz="-4.074E-23"
        iyy="1.2396E-06"
        iyz="-2.9599E-21"
        izz="2.0983E-06" />
    </inertial>
    <visual>
      <origin
        xyz="0 0 0"
        rpy="0 0 0" />
      <geometry>
        <mesh
          filename="package://omni_ballbot/meshes/wheel_link_A.STL" />
      </geometry>
      <material
        name="">
        <color
          rgba="1 1 1 1" />
      </material>
    </visual>
    <collision>
      <origin
        xyz="0 0 0"
        rpy="0 0 0" />
      <geometry>
        <mesh
          filename="package://omni_ballbot/meshes/wheel_link_A.STL" />
      </geometry>
    </collision>
  </link>
  <joint
    name="wheel1_joint_A6"
    type="continuous">
    <origin
      xyz="0 0.045033 0.026"
      rpy="-1.5708 -0.5236 1.5708" />
    <parent
      link="wheel1_base" />
    <child
      link="wheel1_link_A6" />
    <axis
      xyz="0 1 0" />
  </joint>
  <link
    name="wheel1_link_B1">
    <inertial>
      <origin
        xyz="-5.4956E-15 -1.1743E-06 -1.79E-15"
        rpy="0 0 0" />
      <mass
        value="0.0033861" />
      <inertia
        ixx="1.9241E-07"
        ixy="1.5948E-21"
        ixz="7.3079E-25"
        iyy="7.4977E-08"
        iyz="4.2215E-23"
        izz="1.9241E-07" />
    </inertial>
    <visual>
      <origin
        xyz="0 0 0"
        rpy="0 0 0" />
      <geometry>
        <mesh
          filename="package://omni_ballbot/meshes/wheel_link_B.STL" />
      </geometry>
      <material
        name="">
        <color
          rgba="1 1 1 1" />
      </material>
    </visual>
    <collision>
      <origin
        xyz="0 0 0"
        rpy="0 0 0" />
      <geometry>
        <mesh
          filename="package://omni_ballbot/meshes/wheel_link_B.STL" />
      </geometry>
    </collision>
  </link>
  <joint
    name="wheel1_joint_B1"
    type="continuous">
    <origin
      xyz="0 -0.029 0.050229"
      rpy="1.5708 -1.0472 -1.5708" />
    <parent
      link="wheel1_base" />
    <child
      link="wheel1_link_B1" />
    <axis
      xyz="0 1 0" />
  </joint>
  <link
    name="wheel1_link_B2">
    <inertial>
      <origin
        xyz="-5.49560397189452E-15 -1.17428277418216E-06 -1.79110198894605E-15"
        rpy="0 0 0" />
      <mass
        value="0.00338607914041074" />
      <inertia
        ixx="1.92408238575811E-07"
        ixy="-7.61006163548785E-23"
        ixz="-1.84515685483945E-24"
        iyy="7.49769296638009E-08"
        iyz="4.34928877023111E-23"
        izz="1.92408238575811E-07" />
    </inertial>
    <visual>
      <origin
        xyz="0 0 0"
        rpy="0 0 0" />
      <geometry>
        <mesh
          filename="package://omni_ballbot/meshes/wheel_link_B.STL" />
      </geometry>
      <material
        name="">
        <color
          rgba="1 1 1 1" />
      </material>
    </visual>
    <collision>
      <origin
        xyz="0 0 0"
        rpy="0 0 0" />
      <geometry>
        <mesh
          filename="package://omni_ballbot/meshes/wheel_link_B.STL" />
      </geometry>
    </collision>
  </link>
  <joint
    name="wheel1_joint_B2"
    type="continuous">
    <origin
      xyz="0 -0.058 0"
      rpy="1.5708 0 -1.5708" />
    <parent
      link="wheel1_base" />
    <child
      link="wheel1_link_B2" />
    <axis
      xyz="0 1 0" />
  </joint>
  <link
    name="wheel1_link_B3">
    <inertial>
      <origin
        xyz="-1.3878E-17 -1.1743E-06 -8.6736E-19"
        rpy="0 0 0" />
      <mass
        value="0.0033861" />
      <inertia
        ixx="1.9241E-07"
        ixy="-1.2904E-22"
        ixz="6.4542E-24"
        iyy="7.4977E-08"
        iyz="6.2183E-23"
        izz="1.9241E-07" />
    </inertial>
    <visual>
      <origin
        xyz="0 0 0"
        rpy="0 0 0" />
      <geometry>
        <mesh
          filename="package://omni_ballbot/meshes/wheel_link_B.STL" />
      </geometry>
      <material
        name="">
        <color
          rgba="1 1 1 1" />
      </material>
    </visual>
    <collision>
      <origin
        xyz="0 0 0"
        rpy="0 0 0" />
      <geometry>
        <mesh
          filename="package://omni_ballbot/meshes/wheel_link_B.STL" />
      </geometry>
    </collision>
  </link>
  <joint
    name="wheel1_joint_B3"
    type="continuous">
    <origin
      xyz="0 -0.0289999999999999 -0.0502294734194975"
      rpy="1.5707963267949 1.04719755119659 -1.5707963267949" />
    <parent
      link="wheel1_base" />
    <child
      link="wheel1_link_B3" />
    <axis
      xyz="0 1 0" />
  </joint>
  <link
    name="wheel1_link_B4">
    <inertial>
      <origin
        xyz="-5.53723733531797E-15 -1.17428277337725E-06 -1.79066830807706E-15"
        rpy="0 0 0" />
      <mass
        value="0.00338607914041075" />
      <inertia
        ixx="1.9240823857581E-07"
        ixy="1.57660624752607E-21"
        ixz="-4.62521177173431E-25"
        iyy="7.49769296638001E-08"
        iyz="3.91399246050852E-23"
        izz="1.9240823857581E-07" />
    </inertial>
    <visual>
      <origin
        xyz="0 0 0"
        rpy="0 0 0" />
      <geometry>
        <mesh
          filename="package://omni_ballbot/meshes/wheel_link_B.STL" />
      </geometry>
      <material
        name="">
        <color
          rgba="1 1 1 1" />
      </material>
    </visual>
    <collision>
      <origin
        xyz="0 0 0"
        rpy="0 0 0" />
      <geometry>
        <mesh
          filename="package://omni_ballbot/meshes/wheel_link_B.STL" />
      </geometry>
    </collision>
  </link>
  <joint
    name="wheel1_joint_B4"
    type="continuous">
    <origin
      xyz="0 0.029 -0.050229"
      rpy="-1.5708 1.0472 1.5708" />
    <parent
      link="wheel1_base" />
    <child
      link="wheel1_link_B4" />
    <axis
      xyz="0 1 0" />
  </joint>
  <link
    name="wheel1_link_B5">
    <inertial>
      <origin
        xyz="-5.50948175970234E-15 -1.17428277338766E-06 -1.79066830807706E-15"
        rpy="0 0 0" />
      <mass
        value="0.00338607914041074" />
      <inertia
        ixx="1.92408238575811E-07"
        ixy="1.56171699650012E-21"
        ixz="-6.04841401697908E-24"
        iyy="7.49769296638009E-08"
        iyz="1.95624763533928E-24"
        izz="1.92408238575811E-07" />
    </inertial>
    <visual>
      <origin
        xyz="0 0 0"
        rpy="0 0 0" />
      <geometry>
        <mesh
          filename="package://omni_ballbot/meshes/wheel_link_B.STL" />
      </geometry>
      <material
        name="">
        <color
          rgba="1 1 1 1" />
      </material>
    </visual>
    <collision>
      <origin
        xyz="0 0 0"
        rpy="0 0 0" />
      <geometry>
        <mesh
          filename="package://omni_ballbot/meshes/wheel_link_B.STL" />
      </geometry>
    </collision>
  </link>
  <joint
    name="wheel1_joint_B5"
    type="continuous">
    <origin
      xyz="0 0.058 0"
      rpy="-1.5708 0 1.5708" />
    <parent
      link="wheel1_base" />
    <child
      link="wheel1_link_B5" />
    <axis
      xyz="0 1 0" />
  </joint>
  <link
    name="wheel1_link_B6">
    <inertial>
      <origin
        xyz="-5.4956E-15 -1.1743E-06 -1.7913E-15"
        rpy="0 0 0" />
      <mass
        value="0.0033861" />
      <inertia
        ixx="1.9241E-07"
        ixy="-1.3566E-22"
        ixz="1.8681E-24"
        iyy="7.4977E-08"
        iyz="5.3882E-23"
        izz="1.9241E-07" />
    </inertial>
    <visual>
      <origin
        xyz="0 0 0"
        rpy="0 0 0" />
      <geometry>
        <mesh
          filename="package://omni_ballbot/meshes/wheel_link_B.STL" />
      </geometry>
      <material
        name="">
        <color
          rgba="1 1 1 1" />
      </material>
    </visual>
    <collision>
      <origin
        xyz="0 0 0"
        rpy="0 0 0" />
      <geometry>
        <mesh
          filename="package://omni_ballbot/meshes/wheel_link_B.STL" />
      </geometry>
    </collision>
  </link>
  <joint
    name="wheel1_joint_B6"
    type="continuous">
    <origin
      xyz="0 0.029 0.050229"
      rpy="-1.5708 -1.0472 1.5708" />
    <parent
      link="wheel1_base" />
    <child
      link="wheel1_link_B6" />
    <axis
      xyz="0 1 0" />
  </joint>
  

<!--wheel2-->
  <joint
    name="wheel2_joint"
    type="continuous">
    <origin
      xyz="-0.091819 0.15904 -0.081395"
      rpy="0 0.69813 2.0944" />
    <parent
      link="base_link" />
    <child
      link="wheel2_base" />
    <axis
      xyz="1 0 0" />
  </joint>
  <!--wheel2_轮毂-->
  <link
    name="wheel2_base">
    <inertial>
      <origin
        xyz="-1.0842E-18 -6.5486E-17 -3.7297E-17"
        rpy="0 0 0" />
      <mass
        value="0.033709" />
      <inertia
        ixx="1.0185E-05"
        ixy="-1.2283E-23"
        ixz="-7.157E-23"
        iyy="5.1179E-06"
        iyz="1.5882E-21"
        izz="5.1179E-06" />
    </inertial>
    <visual>
      <origin
        xyz="0 0 0"
        rpy="0 0 0" />
      <geometry>
        <mesh
          filename="package://omni_ballbot/meshes/wheel_base.STL" />
      </geometry>
      <material
        name="">
        <color
          rgba="1 1 1 1" />
      </material>
    </visual>
    <collision>
      <origin
        xyz="0 0 0"
        rpy="0 0 0" />
      <geometry>
        <mesh
          filename="package://omni_ballbot/meshes/wheel_base.STL" />
      </geometry>
    </collision>
  </link>
  <link
    name="wheel2_link_A1">
    <inertial>
      <origin
        xyz="1.979E-14 9.4195E-16 -4.0874E-16"
        rpy="0 0 0" />
      <mass
        value="0.016346" />
      <inertia
        ixx="2.0983E-06"
        ixy="-1.9323E-20"
        ixz="-2.7123E-23"
        iyy="1.2396E-06"
        iyz="-2.9302E-21"
        izz="2.0983E-06" />
    </inertial>
    <visual>
      <origin
        xyz="0 0 0"
        rpy="0 0 0" />
      <geometry>
        <mesh
          filename="package://omni_ballbot/meshes/wheel_link_A.STL" />
      </geometry>
      <material
        name="">
        <color
          rgba="1 1 1 1" />
      </material>
    </visual>
    <collision>
      <origin
        xyz="0 0 0"
        rpy="0 0 0" />
      <geometry>
        <mesh
          filename="package://omni_ballbot/meshes/wheel_link_A.STL" />
      </geometry>
    </collision>
  </link>
  <joint
    name="wheel2_joint_A1"
    type="continuous">
    <origin
      xyz="0 0 0.052"
      rpy="0 -1.5708 0" />
    <parent
      link="wheel2_base" />
    <child
      link="wheel2_link_A1" />
    <axis
      xyz="0 1 0" />
  </joint>
  <link
    name="wheel2_link_A2">
    <inertial>
      <origin
        xyz="1.97897254139434E-14 8.22258927613007E-16 -4.09611580765024E-16"
        rpy="0 0 0" />
      <mass
        value="0.0163461071966825" />
      <inertia
        ixx="2.09834716259754E-06"
        ixy="-1.51248320644096E-19"
        ixz="-4.90262679480716E-23"
        iyy="1.23958351383999E-06"
        iyz="-2.9163765855995E-21"
        izz="2.09834716259754E-06" />
    </inertial>
    <visual>
      <origin
        xyz="0 0 0"
        rpy="0 0 0" />
      <geometry>
        <mesh
          filename="package://omni_ballbot/meshes/wheel_link_A.STL" />
      </geometry>
      <material
        name="">
        <color
          rgba="1 1 1 1" />
      </material>
    </visual>
    <collision>
      <origin
        xyz="0 0 0"
        rpy="0 0 0" />
      <geometry>
        <mesh
          filename="package://omni_ballbot/meshes/wheel_link_A.STL" />
      </geometry>
    </collision>
  </link>
  <joint
    name="wheel2_joint_A2"
    type="continuous">
    <origin
      xyz="0 -0.045033 0.026"
      rpy="1.5708 -0.5236 -1.5708" />
    <parent
      link="wheel2_base" />
    <child
      link="wheel2_link_A2" />
    <axis
      xyz="0 1 0" />
  </joint>
  <link
    name="wheel2_link_A3">
    <inertial>
      <origin
        xyz="1.9776E-14 7.494E-16 -4.0961E-16"
        rpy="0 0 0" />
      <mass
        value="0.016346" />
      <inertia
        ixx="2.0983E-06"
        ixy="-2.2896E-20"
        ixz="-4.9433E-23"
        iyy="1.2396E-06"
        iyz="-2.8665E-21"
        izz="2.0983E-06" />
    </inertial>
    <visual>
      <origin
        xyz="0 0 0"
        rpy="0 0 0" />
      <geometry>
        <mesh
          filename="package://omni_ballbot/meshes/wheel_link_A.STL" />
      </geometry>
      <material
        name="">
        <color
          rgba="1 1 1 1" />
      </material>
    </visual>
    <collision>
      <origin
        xyz="0 0 0"
        rpy="0 0 0" />
      <geometry>
        <mesh
          filename="package://omni_ballbot/meshes/wheel_link_A.STL" />
      </geometry>
    </collision>
  </link>
  <joint
    name="wheel2_joint_A3"
    type="continuous">
    <origin
      xyz="0 -0.045033 -0.026"
      rpy="1.5708 0.5236 -1.5708" />
    <parent
      link="wheel2_base" />
    <child
      link="wheel2_link_A3" />
    <axis
      xyz="0 1 0" />
  </joint>
  <link
    name="wheel2_link_A4">
    <inertial>
      <origin
        xyz="-7.63278329429795E-17 7.45931094670027E-17 -1.64798730217797E-17"
        rpy="0 0 0" />
      <mass
        value="0.0163461071966825" />
      <inertia
        ixx="2.09834716259755E-06"
        ixy="-7.30565917006834E-21"
        ixz="-1.9688018747927E-23"
        iyy="1.23958351383999E-06"
        iyz="-2.74827099200293E-21"
        izz="2.09834716259755E-06" />
    </inertial>
    <visual>
      <origin
        xyz="0 0 0"
        rpy="0 0 0" />
      <geometry>
        <mesh
          filename="package://omni_ballbot/meshes/wheel_link_A.STL" />
      </geometry>
      <material
        name="">
        <color
          rgba="1 1 1 1" />
      </material>
    </visual>
    <collision>
      <origin
        xyz="0 0 0"
        rpy="0 0 0" />
      <geometry>
        <mesh
          filename="package://omni_ballbot/meshes/wheel_link_A.STL" />
      </geometry>
    </collision>
  </link>
  <joint
    name="wheel2_joint_A4"
    type="continuous">
    <origin
      xyz="0 0 -0.052"
      rpy="3.1416 1.5708 0" />
    <parent
      link="wheel2_base" />
    <child
      link="wheel2_link_A4" />
    <axis
      xyz="0 1 0" />
  </joint>
  <link
    name="wheel2_link_A5">
    <inertial>
      <origin
        xyz="1.9776E-14 1.2039E-15 -4.0918E-16"
        rpy="0 0 0" />
      <mass
        value="0.016346" />
      <inertia
        ixx="2.0983E-06"
        ixy="-1.4929E-20"
        ixz="-5.3997E-23"
        iyy="1.2396E-06"
        iyz="-2.869E-21"
        izz="2.0983E-06" />
    </inertial>
    <visual>
      <origin
        xyz="0 0 0"
        rpy="0 0 0" />
      <geometry>
        <mesh
          filename="package://omni_ballbot/meshes/wheel_link_A.STL" />
      </geometry>
      <material
        name="">
        <color
          rgba="1 1 1 1" />
      </material>
    </visual>
    <collision>
      <origin
        xyz="0 0 0"
        rpy="0 0 0" />
      <geometry>
        <mesh
          filename="package://omni_ballbot/meshes/wheel_link_A.STL" />
      </geometry>
    </collision>
  </link>
  <joint
    name="wheel2_joint_A5"
    type="continuous">
    <origin
      xyz="0 0.045033 -0.026"
      rpy="-1.5708 0.5236 1.5708" />
    <parent
      link="wheel2_base" />
    <child
      link="wheel2_link_A5" />
    <axis
      xyz="0 1 0" />
  </joint>
  <link
    name="wheel2_link_A6">
    <inertial>
      <origin
        xyz="1.9811E-14 1.0738E-15 -4.0896E-16"
        rpy="0 0 0" />
      <mass
        value="0.016346" />
      <inertia
        ixx="2.0983E-06"
        ixy="-1.7364E-20"
        ixz="-4.074E-23"
        iyy="1.2396E-06"
        iyz="-2.9599E-21"
        izz="2.0983E-06" />
    </inertial>
    <visual>
      <origin
        xyz="0 0 0"
        rpy="0 0 0" />
      <geometry>
        <mesh
          filename="package://omni_ballbot/meshes/wheel_link_A.STL" />
      </geometry>
      <material
        name="">
        <color
          rgba="1 1 1 1" />
      </material>
    </visual>
    <collision>
      <origin
        xyz="0 0 0"
        rpy="0 0 0" />
      <geometry>
        <mesh
          filename="package://omni_ballbot/meshes/wheel_link_A.STL" />
      </geometry>
    </collision>
  </link>
  <joint
    name="wheel2_joint_A6"
    type="continuous">
    <origin
      xyz="0 0.045033 0.026"
      rpy="-1.5708 -0.5236 1.5708" />
    <parent
      link="wheel2_base" />
    <child
      link="wheel2_link_A6" />
    <axis
      xyz="0 1 0" />
  </joint>
  <link
    name="wheel2_link_B1">
    <inertial>
      <origin
        xyz="-5.4956E-15 -1.1743E-06 -1.79E-15"
        rpy="0 0 0" />
      <mass
        value="0.0033861" />
      <inertia
        ixx="1.9241E-07"
        ixy="1.5948E-21"
        ixz="7.3079E-25"
        iyy="7.4977E-08"
        iyz="4.2215E-23"
        izz="1.9241E-07" />
    </inertial>
    <visual>
      <origin
        xyz="0 0 0"
        rpy="0 0 0" />
      <geometry>
        <mesh
          filename="package://omni_ballbot/meshes/wheel_link_B.STL" />
      </geometry>
      <material
        name="">
        <color
          rgba="1 1 1 1" />
      </material>
    </visual>
    <collision>
      <origin
        xyz="0 0 0"
        rpy="0 0 0" />
      <geometry>
        <mesh
          filename="package://omni_ballbot/meshes/wheel_link_B.STL" />
      </geometry>
    </collision>
  </link>
  <joint
    name="wheel2_joint_B1"
    type="continuous">
    <origin
      xyz="0 -0.029 0.050229"
      rpy="1.5708 -1.0472 -1.5708" />
    <parent
      link="wheel2_base" />
    <child
      link="wheel2_link_B1" />
    <axis
      xyz="0 1 0" />
  </joint>
  <link
    name="wheel2_link_B2">
    <inertial>
      <origin
        xyz="-5.49560397189452E-15 -1.17428277418216E-06 -1.79110198894605E-15"
        rpy="0 0 0" />
      <mass
        value="0.00338607914041074" />
      <inertia
        ixx="1.92408238575811E-07"
        ixy="-7.61006163548785E-23"
        ixz="-1.84515685483945E-24"
        iyy="7.49769296638009E-08"
        iyz="4.34928877023111E-23"
        izz="1.92408238575811E-07" />
    </inertial>
    <visual>
      <origin
        xyz="0 0 0"
        rpy="0 0 0" />
      <geometry>
        <mesh
          filename="package://omni_ballbot/meshes/wheel_link_B.STL" />
      </geometry>
      <material
        name="">
        <color
          rgba="1 1 1 1" />
      </material>
    </visual>
    <collision>
      <origin
        xyz="0 0 0"
        rpy="0 0 0" />
      <geometry>
        <mesh
          filename="package://omni_ballbot/meshes/wheel_link_B.STL" />
      </geometry>
    </collision>
  </link>
  <joint
    name="wheel2_joint_B2"
    type="continuous">
    <origin
      xyz="0 -0.058 0"
      rpy="1.5708 0 -1.5708" />
    <parent
      link="wheel2_base" />
    <child
      link="wheel2_link_B2" />
    <axis
      xyz="0 1 0" />
  </joint>
  <link
    name="wheel2_link_B3">
    <inertial>
      <origin
        xyz="-1.3878E-17 -1.1743E-06 -8.6736E-19"
        rpy="0 0 0" />
      <mass
        value="0.0033861" />
      <inertia
        ixx="1.9241E-07"
        ixy="-1.2904E-22"
        ixz="6.4542E-24"
        iyy="7.4977E-08"
        iyz="6.2183E-23"
        izz="1.9241E-07" />
    </inertial>
    <visual>
      <origin
        xyz="0 0 0"
        rpy="0 0 0" />
      <geometry>
        <mesh
          filename="package://omni_ballbot/meshes/wheel_link_B.STL" />
      </geometry>
      <material
        name="">
        <color
          rgba="1 1 1 1" />
      </material>
    </visual>
    <collision>
      <origin
        xyz="0 0 0"
        rpy="0 0 0" />
      <geometry>
        <mesh
          filename="package://omni_ballbot/meshes/wheel_link_B.STL" />
      </geometry>
    </collision>
  </link>
  <joint
    name="wheel2_joint_B3"
    type="continuous">
    <origin
      xyz="0 -0.0289999999999999 -0.0502294734194975"
      rpy="1.5707963267949 1.04719755119659 -1.5707963267949" />
    <parent
      link="wheel2_base" />
    <child
      link="wheel2_link_B3" />
    <axis
      xyz="0 1 0" />
  </joint>
  <link
    name="wheel2_link_B4">
    <inertial>
      <origin
        xyz="-5.53723733531797E-15 -1.17428277337725E-06 -1.79066830807706E-15"
        rpy="0 0 0" />
      <mass
        value="0.00338607914041075" />
      <inertia
        ixx="1.9240823857581E-07"
        ixy="1.57660624752607E-21"
        ixz="-4.62521177173431E-25"
        iyy="7.49769296638001E-08"
        iyz="3.91399246050852E-23"
        izz="1.9240823857581E-07" />
    </inertial>
    <visual>
      <origin
        xyz="0 0 0"
        rpy="0 0 0" />
      <geometry>
        <mesh
          filename="package://omni_ballbot/meshes/wheel_link_B.STL" />
      </geometry>
      <material
        name="">
        <color
          rgba="1 1 1 1" />
      </material>
    </visual>
    <collision>
      <origin
        xyz="0 0 0"
        rpy="0 0 0" />
      <geometry>
        <mesh
          filename="package://omni_ballbot/meshes/wheel_link_B.STL" />
      </geometry>
    </collision>
  </link>
  <joint
    name="wheel2_joint_B4"
    type="continuous">
    <origin
      xyz="0 0.029 -0.050229"
      rpy="-1.5708 1.0472 1.5708" />
    <parent
      link="wheel2_base" />
    <child
      link="wheel2_link_B4" />
    <axis
      xyz="0 1 0" />
  </joint>
  <link
    name="wheel2_link_B5">
    <inertial>
      <origin
        xyz="-5.50948175970234E-15 -1.17428277338766E-06 -1.79066830807706E-15"
        rpy="0 0 0" />
      <mass
        value="0.00338607914041074" />
      <inertia
        ixx="1.92408238575811E-07"
        ixy="1.56171699650012E-21"
        ixz="-6.04841401697908E-24"
        iyy="7.49769296638009E-08"
        iyz="1.95624763533928E-24"
        izz="1.92408238575811E-07" />
    </inertial>
    <visual>
      <origin
        xyz="0 0 0"
        rpy="0 0 0" />
      <geometry>
        <mesh
          filename="package://omni_ballbot/meshes/wheel_link_B.STL" />
      </geometry>
      <material
        name="">
        <color
          rgba="1 1 1 1" />
      </material>
    </visual>
    <collision>
      <origin
        xyz="0 0 0"
        rpy="0 0 0" />
      <geometry>
        <mesh
          filename="package://omni_ballbot/meshes/wheel_link_B.STL" />
      </geometry>
    </collision>
  </link>
  <joint
    name="wheel2_joint_B5"
    type="continuous">
    <origin
      xyz="0 0.058 0"
      rpy="-1.5708 0 1.5708" />
    <parent
      link="wheel2_base" />
    <child
      link="wheel2_link_B5" />
    <axis
      xyz="0 1 0" />
  </joint>
  <link
    name="wheel2_link_B6">
    <inertial>
      <origin
        xyz="-5.4956E-15 -1.1743E-06 -1.7913E-15"
        rpy="0 0 0" />
      <mass
        value="0.0033861" />
      <inertia
        ixx="1.9241E-07"
        ixy="-1.3566E-22"
        ixz="1.8681E-24"
        iyy="7.4977E-08"
        iyz="5.3882E-23"
        izz="1.9241E-07" />
    </inertial>
    <visual>
      <origin
        xyz="0 0 0"
        rpy="0 0 0" />
      <geometry>
        <mesh
          filename="package://omni_ballbot/meshes/wheel_link_B.STL" />
      </geometry>
      <material
        name="">
        <color
          rgba="1 1 1 1" />
      </material>
    </visual>
    <collision>
      <origin
        xyz="0 0 0"
        rpy="0 0 0" />
      <geometry>
        <mesh
          filename="package://omni_ballbot/meshes/wheel_link_B.STL" />
      </geometry>
    </collision>
  </link>
  <joint
    name="wheel2_joint_B6"
    type="continuous">
    <origin
      xyz="0 0.029 0.050229"
      rpy="-1.5708 -1.0472 1.5708" />
    <parent
      link="wheel2_base" />
    <child
      link="wheel2_link_B6" />
    <axis
      xyz="0 1 0" />
  </joint>

<!--wheel3-->
  <joint
    name="wheel3_joint"
    type="continuous">
    <origin
      xyz="-0.091819 -0.15904 -0.081395"
      rpy="0 0.69813 -2.0944" />
    <parent
      link="base_link" />
    <child
      link="wheel3_base" />
    <axis
      xyz="1 0 0" />
  </joint>
  <!--wheel3_轮毂-->
  <link
    name="wheel3_base">
    <inertial>
      <origin
        xyz="-1.0842E-18 -6.5486E-17 -3.7297E-17"
        rpy="0 0 0" />
      <mass
        value="0.033709" />
      <inertia
        ixx="1.0185E-05"
        ixy="-1.2283E-23"
        ixz="-7.157E-23"
        iyy="5.1179E-06"
        iyz="1.5882E-21"
        izz="5.1179E-06" />
    </inertial>
    <visual>
      <origin
        xyz="0 0 0"
        rpy="0 0 0" />
      <geometry>
        <mesh
          filename="package://omni_ballbot/meshes/wheel_base.STL" />
      </geometry>
      <material
        name="">
        <color
          rgba="1 1 1 1" />
      </material>
    </visual>
    <collision>
      <origin
        xyz="0 0 0"
        rpy="0 0 0" />
      <geometry>
        <mesh
          filename="package://omni_ballbot/meshes/wheel_base.STL" />
      </geometry>
    </collision>
  </link>
  <link
    name="wheel3_link_A1">
    <inertial>
      <origin
        xyz="1.979E-14 9.4195E-16 -4.0874E-16"
        rpy="0 0 0" />
      <mass
        value="0.016346" />
      <inertia
        ixx="2.0983E-06"
        ixy="-1.9323E-20"
        ixz="-2.7123E-23"
        iyy="1.2396E-06"
        iyz="-2.9302E-21"
        izz="2.0983E-06" />
    </inertial>
    <visual>
      <origin
        xyz="0 0 0"
        rpy="0 0 0" />
      <geometry>
        <mesh
          filename="package://omni_ballbot/meshes/wheel_link_A.STL" />
      </geometry>
      <material
        name="">
        <color
          rgba="1 1 1 1" />
      </material>
    </visual>
    <collision>
      <origin
        xyz="0 0 0"
        rpy="0 0 0" />
      <geometry>
        <mesh
          filename="package://omni_ballbot/meshes/wheel_link_A.STL" />
      </geometry>
    </collision>
  </link>
  <joint
    name="wheel3_joint_A1"
    type="continuous">
    <origin
      xyz="0 0 0.052"
      rpy="0 -1.5708 0" />
    <parent
      link="wheel3_base" />
    <child
      link="wheel3_link_A1" />
    <axis
      xyz="0 1 0" />
  </joint>
  <link
    name="wheel3_link_A2">
    <inertial>
      <origin
        xyz="1.97897254139434E-14 8.22258927613007E-16 -4.09611580765024E-16"
        rpy="0 0 0" />
      <mass
        value="0.0163461071966825" />
      <inertia
        ixx="2.09834716259754E-06"
        ixy="-1.51248320644096E-19"
        ixz="-4.90262679480716E-23"
        iyy="1.23958351383999E-06"
        iyz="-2.9163765855995E-21"
        izz="2.09834716259754E-06" />
    </inertial>
    <visual>
      <origin
        xyz="0 0 0"
        rpy="0 0 0" />
      <geometry>
        <mesh
          filename="package://omni_ballbot/meshes/wheel_link_A.STL" />
      </geometry>
      <material
        name="">
        <color
          rgba="1 1 1 1" />
      </material>
    </visual>
    <collision>
      <origin
        xyz="0 0 0"
        rpy="0 0 0" />
      <geometry>
        <mesh
          filename="package://omni_ballbot/meshes/wheel_link_A.STL" />
      </geometry>
    </collision>
  </link>
  <joint
    name="wheel3_joint_A2"
    type="continuous">
    <origin
      xyz="0 -0.045033 0.026"
      rpy="1.5708 -0.5236 -1.5708" />
    <parent
      link="wheel3_base" />
    <child
      link="wheel3_link_A2" />
    <axis
      xyz="0 1 0" />
  </joint>
  <link
    name="wheel3_link_A3">
    <inertial>
      <origin
        xyz="1.9776E-14 7.494E-16 -4.0961E-16"
        rpy="0 0 0" />
      <mass
        value="0.016346" />
      <inertia
        ixx="2.0983E-06"
        ixy="-2.2896E-20"
        ixz="-4.9433E-23"
        iyy="1.2396E-06"
        iyz="-2.8665E-21"
        izz="2.0983E-06" />
    </inertial>
    <visual>
      <origin
        xyz="0 0 0"
        rpy="0 0 0" />
      <geometry>
        <mesh
          filename="package://omni_ballbot/meshes/wheel_link_A.STL" />
      </geometry>
      <material
        name="">
        <color
          rgba="1 1 1 1" />
      </material>
    </visual>
    <collision>
      <origin
        xyz="0 0 0"
        rpy="0 0 0" />
      <geometry>
        <mesh
          filename="package://omni_ballbot/meshes/wheel_link_A.STL" />
      </geometry>
    </collision>
  </link>
  <joint
    name="wheel3_joint_A3"
    type="continuous">
    <origin
      xyz="0 -0.045033 -0.026"
      rpy="1.5708 0.5236 -1.5708" />
    <parent
      link="wheel3_base" />
    <child
      link="wheel3_link_A3" />
    <axis
      xyz="0 1 0" />
  </joint>
  <link
    name="wheel3_link_A4">
    <inertial>
      <origin
        xyz="-7.63278329429795E-17 7.45931094670027E-17 -1.64798730217797E-17"
        rpy="0 0 0" />
      <mass
        value="0.0163461071966825" />
      <inertia
        ixx="2.09834716259755E-06"
        ixy="-7.30565917006834E-21"
        ixz="-1.9688018747927E-23"
        iyy="1.23958351383999E-06"
        iyz="-2.74827099200293E-21"
        izz="2.09834716259755E-06" />
    </inertial>
    <visual>
      <origin
        xyz="0 0 0"
        rpy="0 0 0" />
      <geometry>
        <mesh
          filename="package://omni_ballbot/meshes/wheel_link_A.STL" />
      </geometry>
      <material
        name="">
        <color
          rgba="1 1 1 1" />
      </material>
    </visual>
    <collision>
      <origin
        xyz="0 0 0"
        rpy="0 0 0" />
      <geometry>
        <mesh
          filename="package://omni_ballbot/meshes/wheel_link_A.STL" />
      </geometry>
    </collision>
  </link>
  <joint
    name="wheel3_joint_A4"
    type="continuous">
    <origin
      xyz="0 0 -0.052"
      rpy="3.1416 1.5708 0" />
    <parent
      link="wheel3_base" />
    <child
      link="wheel3_link_A4" />
    <axis
      xyz="0 1 0" />
  </joint>
  <link
    name="wheel3_link_A5">
    <inertial>
      <origin
        xyz="1.9776E-14 1.2039E-15 -4.0918E-16"
        rpy="0 0 0" />
      <mass
        value="0.016346" />
      <inertia
        ixx="2.0983E-06"
        ixy="-1.4929E-20"
        ixz="-5.3997E-23"
        iyy="1.2396E-06"
        iyz="-2.869E-21"
        izz="2.0983E-06" />
    </inertial>
    <visual>
      <origin
        xyz="0 0 0"
        rpy="0 0 0" />
      <geometry>
        <mesh
          filename="package://omni_ballbot/meshes/wheel_link_A.STL" />
      </geometry>
      <material
        name="">
        <color
          rgba="1 1 1 1" />
      </material>
    </visual>
    <collision>
      <origin
        xyz="0 0 0"
        rpy="0 0 0" />
      <geometry>
        <mesh
          filename="package://omni_ballbot/meshes/wheel_link_A.STL" />
      </geometry>
    </collision>
  </link>
  <joint
    name="wheel3_joint_A5"
    type="continuous">
    <origin
      xyz="0 0.045033 -0.026"
      rpy="-1.5708 0.5236 1.5708" />
    <parent
      link="wheel3_base" />
    <child
      link="wheel3_link_A5" />
    <axis
      xyz="0 1 0" />
  </joint>
  <link
    name="wheel3_link_A6">
    <inertial>
      <origin
        xyz="1.9811E-14 1.0738E-15 -4.0896E-16"
        rpy="0 0 0" />
      <mass
        value="0.016346" />
      <inertia
        ixx="2.0983E-06"
        ixy="-1.7364E-20"
        ixz="-4.074E-23"
        iyy="1.2396E-06"
        iyz="-2.9599E-21"
        izz="2.0983E-06" />
    </inertial>
    <visual>
      <origin
        xyz="0 0 0"
        rpy="0 0 0" />
      <geometry>
        <mesh
          filename="package://omni_ballbot/meshes/wheel_link_A.STL" />
      </geometry>
      <material
        name="">
        <color
          rgba="1 1 1 1" />
      </material>
    </visual>
    <collision>
      <origin
        xyz="0 0 0"
        rpy="0 0 0" />
      <geometry>
        <mesh
          filename="package://omni_ballbot/meshes/wheel_link_A.STL" />
      </geometry>
    </collision>
  </link>
  <joint
    name="wheel3_joint_A6"
    type="continuous">
    <origin
      xyz="0 0.045033 0.026"
      rpy="-1.5708 -0.5236 1.5708" />
    <parent
      link="wheel3_base" />
    <child
      link="wheel3_link_A6" />
    <axis
      xyz="0 1 0" />
  </joint>
  <link
    name="wheel3_link_B1">
    <inertial>
      <origin
        xyz="-5.4956E-15 -1.1743E-06 -1.79E-15"
        rpy="0 0 0" />
      <mass
        value="0.0033861" />
      <inertia
        ixx="1.9241E-07"
        ixy="1.5948E-21"
        ixz="7.3079E-25"
        iyy="7.4977E-08"
        iyz="4.2215E-23"
        izz="1.9241E-07" />
    </inertial>
    <visual>
      <origin
        xyz="0 0 0"
        rpy="0 0 0" />
      <geometry>
        <mesh
          filename="package://omni_ballbot/meshes/wheel_link_B.STL" />
      </geometry>
      <material
        name="">
        <color
          rgba="1 1 1 1" />
      </material>
    </visual>
    <collision>
      <origin
        xyz="0 0 0"
        rpy="0 0 0" />
      <geometry>
        <mesh
          filename="package://omni_ballbot/meshes/wheel_link_B.STL" />
      </geometry>
    </collision>
  </link>
  <joint
    name="wheel3_joint_B1"
    type="continuous">
    <origin
      xyz="0 -0.029 0.050229"
      rpy="1.5708 -1.0472 -1.5708" />
    <parent
      link="wheel3_base" />
    <child
      link="wheel3_link_B1" />
    <axis
      xyz="0 1 0" />
  </joint>
  <link
    name="wheel3_link_B2">
    <inertial>
      <origin
        xyz="-5.49560397189452E-15 -1.17428277418216E-06 -1.79110198894605E-15"
        rpy="0 0 0" />
      <mass
        value="0.00338607914041074" />
      <inertia
        ixx="1.92408238575811E-07"
        ixy="-7.61006163548785E-23"
        ixz="-1.84515685483945E-24"
        iyy="7.49769296638009E-08"
        iyz="4.34928877023111E-23"
        izz="1.92408238575811E-07" />
    </inertial>
    <visual>
      <origin
        xyz="0 0 0"
        rpy="0 0 0" />
      <geometry>
        <mesh
          filename="package://omni_ballbot/meshes/wheel_link_B.STL" />
      </geometry>
      <material
        name="">
        <color
          rgba="1 1 1 1" />
      </material>
    </visual>
    <collision>
      <origin
        xyz="0 0 0"
        rpy="0 0 0" />
      <geometry>
        <mesh
          filename="package://omni_ballbot/meshes/wheel_link_B.STL" />
      </geometry>
    </collision>
  </link>
  <joint
    name="wheel3_joint_B2"
    type="continuous">
    <origin
      xyz="0 -0.058 0"
      rpy="1.5708 0 -1.5708" />
    <parent
      link="wheel3_base" />
    <child
      link="wheel3_link_B2" />
    <axis
      xyz="0 1 0" />
  </joint>
  <link
    name="wheel3_link_B3">
    <inertial>
      <origin
        xyz="-1.3878E-17 -1.1743E-06 -8.6736E-19"
        rpy="0 0 0" />
      <mass
        value="0.0033861" />
      <inertia
        ixx="1.9241E-07"
        ixy="-1.2904E-22"
        ixz="6.4542E-24"
        iyy="7.4977E-08"
        iyz="6.2183E-23"
        izz="1.9241E-07" />
    </inertial>
    <visual>
      <origin
        xyz="0 0 0"
        rpy="0 0 0" />
      <geometry>
        <mesh
          filename="package://omni_ballbot/meshes/wheel_link_B.STL" />
      </geometry>
      <material
        name="">
        <color
          rgba="1 1 1 1" />
      </material>
    </visual>
    <collision>
      <origin
        xyz="0 0 0"
        rpy="0 0 0" />
      <geometry>
        <mesh
          filename="package://omni_ballbot/meshes/wheel_link_B.STL" />
      </geometry>
    </collision>
  </link>
  <joint
    name="wheel3_joint_B3"
    type="continuous">
    <origin
      xyz="0 -0.0289999999999999 -0.0502294734194975"
      rpy="1.5707963267949 1.04719755119659 -1.5707963267949" />
    <parent
      link="wheel3_base" />
    <child
      link="wheel3_link_B3" />
    <axis
      xyz="0 1 0" />
  </joint>
  <link
    name="wheel3_link_B4">
    <inertial>
      <origin
        xyz="-5.53723733531797E-15 -1.17428277337725E-06 -1.79066830807706E-15"
        rpy="0 0 0" />
      <mass
        value="0.00338607914041075" />
      <inertia
        ixx="1.9240823857581E-07"
        ixy="1.57660624752607E-21"
        ixz="-4.62521177173431E-25"
        iyy="7.49769296638001E-08"
        iyz="3.91399246050852E-23"
        izz="1.9240823857581E-07" />
    </inertial>
    <visual>
      <origin
        xyz="0 0 0"
        rpy="0 0 0" />
      <geometry>
        <mesh
          filename="package://omni_ballbot/meshes/wheel_link_B.STL" />
      </geometry>
      <material
        name="">
        <color
          rgba="1 1 1 1" />
      </material>
    </visual>
    <collision>
      <origin
        xyz="0 0 0"
        rpy="0 0 0" />
      <geometry>
        <mesh
          filename="package://omni_ballbot/meshes/wheel_link_B.STL" />
      </geometry>
    </collision>
  </link>
  <joint
    name="wheel3_joint_B4"
    type="continuous">
    <origin
      xyz="0 0.029 -0.050229"
      rpy="-1.5708 1.0472 1.5708" />
    <parent
      link="wheel3_base" />
    <child
      link="wheel3_link_B4" />
    <axis
      xyz="0 1 0" />
  </joint>
  <link
    name="wheel3_link_B5">
    <inertial>
      <origin
        xyz="-5.50948175970234E-15 -1.17428277338766E-06 -1.79066830807706E-15"
        rpy="0 0 0" />
      <mass
        value="0.00338607914041074" />
      <inertia
        ixx="1.92408238575811E-07"
        ixy="1.56171699650012E-21"
        ixz="-6.04841401697908E-24"
        iyy="7.49769296638009E-08"
        iyz="1.95624763533928E-24"
        izz="1.92408238575811E-07" />
    </inertial>
    <visual>
      <origin
        xyz="0 0 0"
        rpy="0 0 0" />
      <geometry>
        <mesh
          filename="package://omni_ballbot/meshes/wheel_link_B.STL" />
      </geometry>
      <material
        name="">
        <color
          rgba="1 1 1 1" />
      </material>
    </visual>
    <collision>
      <origin
        xyz="0 0 0"
        rpy="0 0 0" />
      <geometry>
        <mesh
          filename="package://omni_ballbot/meshes/wheel_link_B.STL" />
      </geometry>
    </collision>
  </link>
  <joint
    name="wheel3_joint_B5"
    type="continuous">
    <origin
      xyz="0 0.058 0"
      rpy="-1.5708 0 1.5708" />
    <parent
      link="wheel3_base" />
    <child
      link="wheel3_link_B5" />
    <axis
      xyz="0 1 0" />
  </joint>
  <link
    name="wheel3_link_B6">
    <inertial>
      <origin
        xyz="-5.4956E-15 -1.1743E-06 -1.7913E-15"
        rpy="0 0 0" />
      <mass
        value="0.0033861" />
      <inertia
        ixx="1.9241E-07"
        ixy="-1.3566E-22"
        ixz="1.8681E-24"
        iyy="7.4977E-08"
        iyz="5.3882E-23"
        izz="1.9241E-07" />
    </inertial>
    <visual>
      <origin
        xyz="0 0 0"
        rpy="0 0 0" />
      <geometry>
        <mesh
          filename="package://omni_ballbot/meshes/wheel_link_B.STL" />
      </geometry>
      <material
        name="">
        <color
          rgba="1 1 1 1" />
      </material>
    </visual>
    <collision>
      <origin
        xyz="0 0 0"
        rpy="0 0 0" />
      <geometry>
        <mesh
          filename="package://omni_ballbot/meshes/wheel_link_B.STL" />
      </geometry>
    </collision>
  </link>
  <joint
    name="wheel3_joint_B6"
    type="continuous">
    <origin
      xyz="0 0.029 0.050229"
      rpy="-1.5708 -1.0472 1.5708" />
    <parent
      link="wheel3_base" />
    <child
      link="wheel3_link_B6" />
    <axis
      xyz="0 1 0" />
  </joint>



</robot>